2024-03-16 12:23:52,141 ERROR /Users/timur_1/PycharmProjects/NewsPortal/venv/lib/python3.11/site-packages/django/utils/log.py Internal Server Error: /news/ (<class 'django.template.exceptions.TemplateSyntaxError'>, TemplateSyntaxError("'trans' takes at least one argument"), <traceback object at 0x10666b640>)
Traceback (most recent call last):
  File "/Users/timur_1/PycharmProjects/NewsPortal/venv/lib/python3.11/site-packages/django/core/handlers/exception.py", line 55, in inner
    response = get_response(request)
               ^^^^^^^^^^^^^^^^^^^^^
  File "/Users/timur_1/PycharmProjects/NewsPortal/venv/lib/python3.11/site-packages/django/core/handlers/base.py", line 220, in _get_response
    response = response.render()
               ^^^^^^^^^^^^^^^^^
  File "/Users/timur_1/PycharmProjects/NewsPortal/venv/lib/python3.11/site-packages/django/template/response.py", line 114, in render
    self.content = self.rendered_content
                   ^^^^^^^^^^^^^^^^^^^^^
  File "/Users/timur_1/PycharmProjects/NewsPortal/venv/lib/python3.11/site-packages/django/template/response.py", line 90, in rendered_content
    template = self.resolve_template(self.template_name)
               ^^^^^^^^^^^^^^^^^^^^^^^^^^^^^^^^^^^^^^^^^
  File "/Users/timur_1/PycharmProjects/NewsPortal/venv/lib/python3.11/site-packages/django/template/response.py", line 72, in resolve_template
    return select_template(template, using=self.using)
           ^^^^^^^^^^^^^^^^^^^^^^^^^^^^^^^^^^^^^^^^^^^
  File "/Users/timur_1/PycharmProjects/NewsPortal/venv/lib/python3.11/site-packages/django/template/loader.py", line 42, in select_template
    return engine.get_template(template_name)
           ^^^^^^^^^^^^^^^^^^^^^^^^^^^^^^^^^^
  File "/Users/timur_1/PycharmProjects/NewsPortal/venv/lib/python3.11/site-packages/django/template/backends/django.py", line 33, in get_template
    return Template(self.engine.get_template(template_name), self)
                    ^^^^^^^^^^^^^^^^^^^^^^^^^^^^^^^^^^^^^^^
  File "/Users/timur_1/PycharmProjects/NewsPortal/venv/lib/python3.11/site-packages/django/template/engine.py", line 175, in get_template
    template, origin = self.find_template(template_name)
                       ^^^^^^^^^^^^^^^^^^^^^^^^^^^^^^^^^
  File "/Users/timur_1/PycharmProjects/NewsPortal/venv/lib/python3.11/site-packages/django/template/engine.py", line 157, in find_template
    template = loader.get_template(name, skip=skip)
               ^^^^^^^^^^^^^^^^^^^^^^^^^^^^^^^^^^^^
  File "/Users/timur_1/PycharmProjects/NewsPortal/venv/lib/python3.11/site-packages/django/template/loaders/cached.py", line 57, in get_template
    template = super().get_template(template_name, skip)
               ^^^^^^^^^^^^^^^^^^^^^^^^^^^^^^^^^^^^^^^^^
  File "/Users/timur_1/PycharmProjects/NewsPortal/venv/lib/python3.11/site-packages/django/template/loaders/base.py", line 28, in get_template
    return Template(
           ^^^^^^^^^
  File "/Users/timur_1/PycharmProjects/NewsPortal/venv/lib/python3.11/site-packages/django/template/base.py", line 154, in __init__
    self.nodelist = self.compile_nodelist()
                    ^^^^^^^^^^^^^^^^^^^^^^^
  File "/Users/timur_1/PycharmProjects/NewsPortal/venv/lib/python3.11/site-packages/django/template/base.py", line 196, in compile_nodelist
    return parser.parse()
           ^^^^^^^^^^^^^^
  File "/Users/timur_1/PycharmProjects/NewsPortal/venv/lib/python3.11/site-packages/django/template/base.py", line 510, in parse
    raise self.error(token, e)
  File "/Users/timur_1/PycharmProjects/NewsPortal/venv/lib/python3.11/site-packages/django/template/base.py", line 508, in parse
    compiled_result = compile_func(self, token)
                      ^^^^^^^^^^^^^^^^^^^^^^^^^
  File "/Users/timur_1/PycharmProjects/NewsPortal/venv/lib/python3.11/site-packages/django/template/loader_tags.py", line 295, in do_extends
    nodelist = parser.parse()
               ^^^^^^^^^^^^^^
  File "/Users/timur_1/PycharmProjects/NewsPortal/venv/lib/python3.11/site-packages/django/template/base.py", line 510, in parse
    raise self.error(token, e)
  File "/Users/timur_1/PycharmProjects/NewsPortal/venv/lib/python3.11/site-packages/django/template/base.py", line 508, in parse
    compiled_result = compile_func(self, token)
                      ^^^^^^^^^^^^^^^^^^^^^^^^^
  File "/Users/timur_1/PycharmProjects/NewsPortal/venv/lib/python3.11/site-packages/django/templatetags/i18n.py", line 402, in do_translate
    raise TemplateSyntaxError("'%s' takes at least one argument" % bits[0])
django.template.exceptions.TemplateSyntaxError: 'trans' takes at least one argument
2024-03-16 12:23:52,144 ERROR /Users/timur_1/PycharmProjects/NewsPortal/venv/lib/python3.11/site-packages/django/core/servers/basehttp.py "GET /news/ HTTP/1.1" 500 185212 None
2024-03-16 14:45:03,322 ERROR /Users/timur_1/PycharmProjects/NewsPortal/venv/lib/python3.11/site-packages/django/utils/log.py Internal Server Error: /news/create/ (<class 'kombu.exceptions.OperationalError'>, OperationalError('Error 61 connecting to localhost:6379. Connection refused.'), <traceback object at 0x10480e440>)
Traceback (most recent call last):
  File "/Users/timur_1/PycharmProjects/NewsPortal/venv/lib/python3.11/site-packages/redis/connection.py", line 264, in connect
    sock = self.retry.call_with_retry(
           ^^^^^^^^^^^^^^^^^^^^^^^^^^^
  File "/Users/timur_1/PycharmProjects/NewsPortal/venv/lib/python3.11/site-packages/redis/retry.py", line 46, in call_with_retry
    return do()
           ^^^^
  File "/Users/timur_1/PycharmProjects/NewsPortal/venv/lib/python3.11/site-packages/redis/connection.py", line 265, in <lambda>
    lambda: self._connect(), lambda error: self.disconnect(error)
            ^^^^^^^^^^^^^^^
  File "/Users/timur_1/PycharmProjects/NewsPortal/venv/lib/python3.11/site-packages/redis/connection.py", line 627, in _connect
    raise err
  File "/Users/timur_1/PycharmProjects/NewsPortal/venv/lib/python3.11/site-packages/redis/connection.py", line 615, in _connect
    sock.connect(socket_address)
ConnectionRefusedError: [Errno 61] Connection refused

During handling of the above exception, another exception occurred:

Traceback (most recent call last):
  File "/Users/timur_1/PycharmProjects/NewsPortal/venv/lib/python3.11/site-packages/celery/backends/redis.py", line 127, in reconnect_on_error
    yield
  File "/Users/timur_1/PycharmProjects/NewsPortal/venv/lib/python3.11/site-packages/celery/backends/redis.py", line 177, in _consume_from
    self._pubsub.subscribe(key)
  File "/Users/timur_1/PycharmProjects/NewsPortal/venv/lib/python3.11/site-packages/redis/client.py", line 916, in subscribe
    ret_val = self.execute_command("SUBSCRIBE", *new_channels.keys())
              ^^^^^^^^^^^^^^^^^^^^^^^^^^^^^^^^^^^^^^^^^^^^^^^^^^^^^^^
  File "/Users/timur_1/PycharmProjects/NewsPortal/venv/lib/python3.11/site-packages/redis/client.py", line 749, in execute_command
    self.connection = self.connection_pool.get_connection(
                      ^^^^^^^^^^^^^^^^^^^^^^^^^^^^^^^^^^^^
  File "/Users/timur_1/PycharmProjects/NewsPortal/venv/lib/python3.11/site-packages/redis/connection.py", line 1086, in get_connection
    connection.connect()
  File "/Users/timur_1/PycharmProjects/NewsPortal/venv/lib/python3.11/site-packages/redis/connection.py", line 270, in connect
    raise ConnectionError(self._error_message(e))
redis.exceptions.ConnectionError: Error 61 connecting to localhost:6379. Connection refused.

During handling of the above exception, another exception occurred:

Traceback (most recent call last):
  File "/Users/timur_1/PycharmProjects/NewsPortal/venv/lib/python3.11/site-packages/redis/connection.py", line 264, in connect
    sock = self.retry.call_with_retry(
           ^^^^^^^^^^^^^^^^^^^^^^^^^^^
  File "/Users/timur_1/PycharmProjects/NewsPortal/venv/lib/python3.11/site-packages/redis/retry.py", line 46, in call_with_retry
    return do()
           ^^^^
  File "/Users/timur_1/PycharmProjects/NewsPortal/venv/lib/python3.11/site-packages/redis/connection.py", line 265, in <lambda>
    lambda: self._connect(), lambda error: self.disconnect(error)
            ^^^^^^^^^^^^^^^
  File "/Users/timur_1/PycharmProjects/NewsPortal/venv/lib/python3.11/site-packages/redis/connection.py", line 627, in _connect
    raise err
  File "/Users/timur_1/PycharmProjects/NewsPortal/venv/lib/python3.11/site-packages/redis/connection.py", line 615, in _connect
    sock.connect(socket_address)
ConnectionRefusedError: [Errno 61] Connection refused

During handling of the above exception, another exception occurred:

Traceback (most recent call last):
  File "/Users/timur_1/PycharmProjects/NewsPortal/venv/lib/python3.11/site-packages/kombu/connection.py", line 472, in _reraise_as_library_errors
    yield
  File "/Users/timur_1/PycharmProjects/NewsPortal/venv/lib/python3.11/site-packages/celery/app/base.py", line 798, in send_task
    self.backend.on_task_call(P, task_id)
  File "/Users/timur_1/PycharmProjects/NewsPortal/venv/lib/python3.11/site-packages/celery/backends/redis.py", line 373, in on_task_call
    self.result_consumer.consume_from(task_id)
  File "/Users/timur_1/PycharmProjects/NewsPortal/venv/lib/python3.11/site-packages/celery/backends/redis.py", line 169, in consume_from
    return self.start(task_id)
           ^^^^^^^^^^^^^^^^^^^
  File "/Users/timur_1/PycharmProjects/NewsPortal/venv/lib/python3.11/site-packages/celery/backends/redis.py", line 147, in start
    self._consume_from(initial_task_id)
  File "/Users/timur_1/PycharmProjects/NewsPortal/venv/lib/python3.11/site-packages/celery/backends/redis.py", line 176, in _consume_from
    with self.reconnect_on_error():
  File "/Library/Frameworks/Python.framework/Versions/3.11/lib/python3.11/contextlib.py", line 155, in __exit__
    self.gen.throw(typ, value, traceback)
  File "/Users/timur_1/PycharmProjects/NewsPortal/venv/lib/python3.11/site-packages/celery/backends/redis.py", line 130, in reconnect_on_error
    self._ensure(self._reconnect_pubsub, ())
  File "/Users/timur_1/PycharmProjects/NewsPortal/venv/lib/python3.11/site-packages/celery/backends/redis.py", line 384, in ensure
    return retry_over_time(
           ^^^^^^^^^^^^^^^^
  File "/Users/timur_1/PycharmProjects/NewsPortal/venv/lib/python3.11/site-packages/kombu/utils/functional.py", line 318, in retry_over_time
    return fun(*args, **kwargs)
           ^^^^^^^^^^^^^^^^^^^^
  File "/Users/timur_1/PycharmProjects/NewsPortal/venv/lib/python3.11/site-packages/celery/backends/redis.py", line 106, in _reconnect_pubsub
    metas = self.backend.client.mget(self.subscribed_to)
            ^^^^^^^^^^^^^^^^^^^^^^^^^^^^^^^^^^^^^^^^^^^^
  File "/Users/timur_1/PycharmProjects/NewsPortal/venv/lib/python3.11/site-packages/redis/commands/core.py", line 2015, in mget
    return self.execute_command("MGET", *args, **options)
           ^^^^^^^^^^^^^^^^^^^^^^^^^^^^^^^^^^^^^^^^^^^^^^
  File "/Users/timur_1/PycharmProjects/NewsPortal/venv/lib/python3.11/site-packages/redis/client.py", line 533, in execute_command
    conn = self.connection or pool.get_connection(command_name, **options)
                              ^^^^^^^^^^^^^^^^^^^^^^^^^^^^^^^^^^^^^^^^^^^^
  File "/Users/timur_1/PycharmProjects/NewsPortal/venv/lib/python3.11/site-packages/redis/connection.py", line 1086, in get_connection
    connection.connect()
  File "/Users/timur_1/PycharmProjects/NewsPortal/venv/lib/python3.11/site-packages/redis/connection.py", line 270, in connect
    raise ConnectionError(self._error_message(e))
redis.exceptions.ConnectionError: Error 61 connecting to localhost:6379. Connection refused.

The above exception was the direct cause of the following exception:

Traceback (most recent call last):
  File "/Users/timur_1/PycharmProjects/NewsPortal/venv/lib/python3.11/site-packages/django/core/handlers/exception.py", line 55, in inner
    response = get_response(request)
               ^^^^^^^^^^^^^^^^^^^^^
  File "/Users/timur_1/PycharmProjects/NewsPortal/venv/lib/python3.11/site-packages/django/core/handlers/base.py", line 197, in _get_response
    response = wrapped_callback(request, *callback_args, **callback_kwargs)
               ^^^^^^^^^^^^^^^^^^^^^^^^^^^^^^^^^^^^^^^^^^^^^^^^^^^^^^^^^^^^
  File "/Users/timur_1/PycharmProjects/NewsPortal/venv/lib/python3.11/site-packages/django/views/generic/base.py", line 104, in view
    return self.dispatch(request, *args, **kwargs)
           ^^^^^^^^^^^^^^^^^^^^^^^^^^^^^^^^^^^^^^^
  File "/Users/timur_1/PycharmProjects/NewsPortal/venv/lib/python3.11/site-packages/django/contrib/auth/mixins.py", line 73, in dispatch
    return super().dispatch(request, *args, **kwargs)
           ^^^^^^^^^^^^^^^^^^^^^^^^^^^^^^^^^^^^^^^^^^
  File "/Users/timur_1/PycharmProjects/NewsPortal/venv/lib/python3.11/site-packages/django/contrib/auth/mixins.py", line 109, in dispatch
    return super().dispatch(request, *args, **kwargs)
           ^^^^^^^^^^^^^^^^^^^^^^^^^^^^^^^^^^^^^^^^^^
  File "/Users/timur_1/PycharmProjects/NewsPortal/venv/lib/python3.11/site-packages/django/views/generic/base.py", line 143, in dispatch
    return handler(request, *args, **kwargs)
           ^^^^^^^^^^^^^^^^^^^^^^^^^^^^^^^^^
  File "/Users/timur_1/PycharmProjects/NewsPortal/venv/lib/python3.11/site-packages/django/views/generic/edit.py", line 182, in post
    return super().post(request, *args, **kwargs)
           ^^^^^^^^^^^^^^^^^^^^^^^^^^^^^^^^^^^^^^
  File "/Users/timur_1/PycharmProjects/NewsPortal/venv/lib/python3.11/site-packages/django/views/generic/edit.py", line 151, in post
    return self.form_valid(form)
           ^^^^^^^^^^^^^^^^^^^^^
  File "/Users/timur_1/PycharmProjects/NewsPortal/NewsPaper/rest/views.py", line 70, in form_valid
    send_mails.delay(post.pk)
  File "/Users/timur_1/PycharmProjects/NewsPortal/venv/lib/python3.11/site-packages/celery/app/task.py", line 444, in delay
    return self.apply_async(args, kwargs)
           ^^^^^^^^^^^^^^^^^^^^^^^^^^^^^^
  File "/Users/timur_1/PycharmProjects/NewsPortal/venv/lib/python3.11/site-packages/celery/app/task.py", line 594, in apply_async
    return app.send_task(
           ^^^^^^^^^^^^^^
  File "/Users/timur_1/PycharmProjects/NewsPortal/venv/lib/python3.11/site-packages/celery/app/base.py", line 796, in send_task
    with P.connection._reraise_as_library_errors():
  File "/Library/Frameworks/Python.framework/Versions/3.11/lib/python3.11/contextlib.py", line 155, in __exit__
    self.gen.throw(typ, value, traceback)
  File "/Users/timur_1/PycharmProjects/NewsPortal/venv/lib/python3.11/site-packages/kombu/connection.py", line 476, in _reraise_as_library_errors
    raise ConnectionError(str(exc)) from exc
kombu.exceptions.OperationalError: Error 61 connecting to localhost:6379. Connection refused.
